
<mujocoinclude>
    <body name="a_right" pos="0.469 0.5 0" euler="0 0 3.1416">
        <geom quat="0.707107 0 0 0.707107" type="mesh" mesh="a1_1_base" name="a1_right/1_base" contype="0" conaffinity="0"/>

        <body name="a1_right/shoulder_link" pos="0 0 0.079">
            <inertial pos="-1.4403e-06 -0.00074041 0.056573" quat="0.707084 0.00122867 -0.00107609 0.707127" mass="0.95" diaginertia="0.000708573 0.00058101 0.000445827"/>
            <joint name="a1_right/waist" pos="0 0 0" axis="0 0 1" limited="true" range="-3.14158 3.14158" frictionloss="50" />
            <geom pos="0 0 -0.003" quat="0.707107 0 0 0.707107" type="mesh" mesh="a1_2_shoulder" name="a1_right/2_shoulder" />
            
            <body name="a1_right/upper_arm_link" pos="0 0 0.04805">
                <inertial pos="0.23622 0.016356 9.154e-05" quat="0.484393 0.48518 0.524693 0.504639" mass="1" diaginertia="0.00761886 0.00757469 0.000578276"/>
                <joint name="a1_right/shoulder" pos="0 0 0" axis="0 1 0" limited="true" range="-1.85005 1.25664" frictionloss="60" />
                <geom quat="0.707107 0 0 0.707107" type="mesh" mesh="a1_3_upper_arm" name="a1_right/3_upper_arm"/>
                
                <body name="a1_right/upper_forearm_link" pos="0.05955 0 0.3">
                    <inertial pos="0.054443 0.045347 0.00042807" quat="0.595278 0.471808 -0.522016 0.387995" mass="0.7" diaginertia="0.00149749 0.00144877 0.00053598"/>
                    <joint name="a1_right/elbow" pos="0 0 0" axis="0 1 0" limited="true" range="-1.76278 1.6057" frictionloss="60" />
                    <geom type="mesh" mesh="a1_4_upper_forearm" name="a1_right/4_upper_forearm" />
                    
                    <body name="a1_right/lower_forearm_link" pos="0.2 0 0">
                        <inertial pos="7.6256e-07 -0.0021448 0.27415" quat="0.70651 0.0169198 -0.0168252 0.707301" mass="0.4" diaginertia="0.000101779 9.7042e-05 8.44616e-05"/>
                        <joint name="a1_right/forearm_roll" pos="0 0 0" axis="1 0 0" limited="true" range="-3.14158 3.14158" frictionloss="30" />
                        <geom quat="0 1 0 0" type="mesh" mesh="a1_5_lower_forearm" name="a1_right/5_lower_forearm"/>
                        
                        <body name="a1_right/wrist_link" pos="0.1 0 0">
                            <inertial pos="-3.9997e-06 -0.05431 0.0034482" quat="0.477398 0.87868 0.00338218 -0.000840949" mass="0.3" diaginertia="0.00011332 0.000109027 7.34689e-05"/>
                            <joint name="a1_right/wrist_angle" pos="0 0 0" axis="0 1 0" limited="true" range="-1.8675 2.23402" frictionloss="30" />
                            <geom quat="0.707107 0 0 0.707107" type="mesh" mesh="a1_6_wrist" name="a1_right/6_wrist" />
                            
                            <body name="a1_right/gripper_link" pos="0.069744 0 0">
                                
                                <body name="a1_right/camera_focus" pos="0.15 0 0.01">
                                    <site pos="0 0 0" size="0.01" type="sphere" name="right_cam_focus" rgba="0 0 1 0"/>
                                </body>
                                
                                <site pos="0.15 0 0" size="0.003 0.003 0.03" type="box" name="cali_right_site1" rgba="0 0 1 0"/>
                                <site pos="0.15 0 0" size="0.003 0.03 0.003" type="box" name="cali_right_site2" rgba="0 0 1 0"/>
                                <site pos="0.15 0 0" size="0.03 0.003 0.003" type="box" name="cali_right_site3" rgba="0 0 1 0"/>
                                
                                <camera name="right_wrist" pos="-0.1 0 0.16" fovy="20" mode="targetbody" target="a1_right/camera_focus"/>
                                <inertial pos="2.406e-06 -9.4582e-08 -0.038796" quat="1 -8.0778e-06 -0.000185306 8.09142e-05" mass="0.35" diaginertia="0.00011445 0.00011239 7.4519e-05"/>
                                <joint name="a1_right/wrist_rotate" pos="0 0 0" axis="1 0 0" limited="true" range="-3.14158 3.14158" frictionloss="30" />
                                <geom pos="-0.02 0 0" quat="0.707107 0 0 0.707107" type="mesh" mesh="a1_7_gripper" name="a1_right/7_gripper" />
                                

                            </body>
                        </body>
                    </body>
                </body>
            </body>
        </body>
    </body>

</mujocoinclude>